<?xml version="1.0"?>
<robot xmlns:xacro="http://www.ros.org/wiki/xacro" name="mbot">
<xacro:property name="base_radius" value=".15" />
<xacro:property name="base_length" value=".25" />
<xacro:property name="screen_length" value=".18" />
<xacro:property name="screen_width" value=".12" />
<xacro:property name="screen_thickness" value=".01" />
<xacro:property name="wheel_length" value=".05" />
<xacro:property name="wheel_radius" value=".03" />
<xacro:property name="wheel_mass" value="0.5" />
<xacro:property name="screen_mass" value="0.2" />
<xacro:property name="base_mass" value="2" />
<xacro:property name="head_mass" value="1" />
<xacro:property name="inertia_head" value="0.018" />
<xacro:property name="inertia_base" value="0.2364" />
<xacro:property name="inertia_wheels" value="0.0002" />
<xacro:property name="camera_link" value="0.025" />
<xacro:property name="imu_link" value="0.025" />
<xacro:property name="hand_length" value="0.2" />
<xacro:property name="hand_thickness" value="0.1" />
<xacro:property name="hand_mass" value="0.05" />

  <link name="base_link">
    <visual>
      <geometry>
        <cylinder length="${base_length}" radius="${base_radius}"/>
      </geometry>
    </visual>
    <collision>
      <geometry>
        <cylinder length="${base_length}" radius="${base_radius}"/>
      </geometry>
    </collision>
    <inertial>
      <mass value="${base_mass}"/>
      <inertia ixx="${inertia_base}" ixy="0.0" ixz="0.0" iyy="${inertia_base}" iyz="0.0" izz="${inertia_base}"/>
    </inertial>
  </link>

  <link name="head">
    <visual>
      <geometry>
        <sphere radius="${base_radius}"/>
      </geometry>
    </visual>
    <collision>
      <geometry>
        <sphere radius="${base_radius}"/>
      </geometry>
    </collision>
    <inertial>
      <mass value="${head_mass}"/>
      <inertia ixx="${inertia_head}" ixy="0.0" ixz="0.0" iyy="${inertia_head}" iyz="0.0" izz="${inertia_head}"/>
    </inertial>
  </link>

  <joint name="head_swivel" type="fixed">
    <parent link="base_link"/>
    <child link="head"/>
    <origin xyz="0 0 0.15"/>
    <axis xyz="0 0 1" />
  </joint>

  <link name="box">
    <visual>
      <geometry>
        <box size="${screen_length} ${screen_thickness} ${screen_width}"/>
      </geometry>
      <origin rpy="-0.5235 0 1.57" xyz="0 0 0"/>
    </visual>
    <collision>
      <geometry>
        <box size="${screen_length} ${screen_thickness} ${screen_width}"/>
      </geometry>
    </collision>
    <inertial>
      <mass value="${screen_mass}"/>
      <inertia ixx="0.00000" ixy="0.0" ixz="0.0" iyy="0.00000" iyz="0.0" izz="0.00000"/>
    </inertial>
  </link>

  <joint name="tobox" type="fixed">
    <parent link="head"/>
    <child link="box"/>
    <origin xyz="0.12 0 0.08"/>
  </joint>

  <link name="right_front_wheel">
    <visual>
      <geometry>
        <cylinder length="${wheel_length}" radius="${wheel_radius}"/>
      </geometry>
    </visual>
    <collision>
      <geometry>
        <cylinder length="${wheel_length}" radius="${wheel_radius}"/>
      </geometry>
    </collision>
    <inertial>
      <mass value="${wheel_mass}"/>
      <inertia ixx="${inertia_wheels}" ixy="0.0" ixz="0.0" iyy="${inertia_wheels}" iyz="0.0" izz="${inertia_wheels}"/>
    </inertial>
  </link>

  <joint name="right_front_wheel_joint" type="continuous">
    <parent link="base_link"/>
    <child link="right_front_wheel"/>
    <axis xyz="0 0 1" />
    <origin rpy="-1.57 0 0" xyz="0.1 -0.1 -0.125"/>
  </joint>

  <link name="right_back_wheel">
    <visual>
      <geometry>
        <cylinder length="${wheel_length}" radius="${wheel_radius}"/>
      </geometry>
    </visual>
    <collision>
      <geometry>
        <cylinder length="${wheel_length}" radius="${wheel_radius}"/>
      </geometry>
    </collision>
    <inertial>
      <mass value="${wheel_mass}"/>
      <inertia ixx="${inertia_wheels}" ixy="0.0" ixz="0.0" iyy="${inertia_wheels}" iyz="0.0" izz="${inertia_wheels}"/>
    </inertial>
  </link>

  <joint name="right_back_wheel_joint" type="continuous">
    <parent link="base_link"/>
    <child link="right_back_wheel"/>
    <origin rpy="-1.57 0 0" xyz="-0.1 -0.1 -0.125"/>
    <axis xyz="0 0 1" />
  </joint>

  <link name="left_front_wheel">
    <visual>
      <geometry>
        <cylinder length="${wheel_length}" radius="${wheel_radius}"/>
      </geometry>
    </visual>
    <collision>
      <geometry>
        <cylinder length="${wheel_length}" radius="${wheel_radius}"/>
      </geometry>
    </collision>
    <inertial>
      <mass value="${wheel_mass}"/>
      <inertia ixx="${inertia_wheels}" ixy="0.0" ixz="0.0" iyy="${inertia_wheels}" iyz="0.0" izz="${inertia_wheels}"/>
    </inertial>
  </link>

  <joint name="left_front_wheel_joint" type="continuous">
    <parent link="base_link"/>
    <child link="left_front_wheel"/>
    <origin rpy="-1.57 0 0" xyz="0.1 0.1 -0.125"/>
    <axis xyz="0 0 1" />
  </joint>

  <link name="left_back_wheel">
    <visual>
      <geometry>
        <cylinder length="${wheel_length}" radius="${wheel_radius}"/>
      </geometry>
    </visual>
    <collision>
      <geometry>
        <cylinder length="${wheel_length}" radius="${wheel_radius}"/>
      </geometry>
    </collision>
    <inertial>
      <mass value="${wheel_mass}"/>
      <inertia ixx="${inertia_wheels}" ixy="0.0" ixz="0.0" iyy="${inertia_wheels}" iyz="0.0" izz="${inertia_wheels}"/>
    </inertial>
  </link>

  <joint name="left_back_wheel_joint" type="continuous">
    <parent link="base_link"/>
    <child link="left_back_wheel"/>
    <origin rpy="-1.57 0 0" xyz="-0.1 0.1 -0.125"/>
    <axis xyz="0 0 1" />
  </joint>

  <!-- <link name="hand_right">
    <visual>
      <geometry>
        <box size="${hand_length} ${hand_thickness} ${hand_thickness}"/>
      </geometry>
      <origin rpy="0 1.5707 0" xyz="-0.05 0 0.1"/>
    </visual>
    <collision>
      <geometry>
        <box size="${hand_length} ${hand_thickness} ${hand_thickness}"/>
      </geometry>
    </collision>
    <inertial>
      <mass value="${hand_mass}"/>
      <inertia ixx="0.01" ixy="0.0" ixz="0.0" iyy="0.01" iyz="0.0" izz="0.01"/>
    </inertial>
  </link>

  <joint name="right_hand_base_joint" type="continuous">
    <parent link="base_link"/>
    <child link="hand_right"/>
    <origin xyz="0 -0.15 0.125"/>
    <axis xyz="1 0 0" />
  </joint>

  <link name="hand_left">
    <visual>
      <geometry>
        <box size="${hand_length} ${hand_thickness} ${hand_thickness}"/>
      </geometry>
      <origin rpy="0 1.5707 0" xyz="+0.05 0 0.1"/>
    </visual>
    <collision>
      <geometry>
        <box size="${hand_length} ${hand_thickness} ${hand_thickness}"/>
      </geometry>
    </collision>
    <inertial>
      <mass value="${hand_mass}"/>
      <inertia ixx="0.01" ixy="0.0" ixz="0.0" iyy="0.01" iyz="0.0" izz="0.01"/>
    </inertial>
  </link>

  <joint name="left_hand_base_joint" type="continuous">
    <parent link="base_link"/>
    <child link="hand_left"/>
    <origin xyz="0 0.15 0.125"/>
    <axis xyz="1 0 0" />
  </joint>
 -->

  <!-- Hokuyo Laser -->
  <link name="hokuyo_link">
    <collision>
      <origin xyz="0 0 0" rpy="0 0 0"/>
      <geometry>
    <box size="0.1 0.1 0.1"/>
      </geometry>
    </collision>

    <visual>
      <origin xyz="0 0 0" rpy="0 0 0"/>
      <geometry>
        <mesh filename="package://mbot_description/meshes/hokuyo.dae"/>
      </geometry>
    </visual>

    <inertial>
      <mass value="1e-5" />
      <origin xyz="0 0 0" rpy="0 0 0"/>
      <inertia ixx="1e-6" ixy="0" ixz="0" iyy="1e-6" iyz="0" izz="1e-6" />
    </inertial>
  </link>

  <joint name="hokuyo_joint" type="fixed">
    <axis xyz="0 0 1" />
    <origin xyz="0.15 0 -0.1" rpy="0 0 0"/>
    <parent link="head"/>
    <child link="hokuyo_link"/>
  </joint>

  <!-- hokuyo -->
  <gazebo reference="hokuyo_link">
    <sensor type="ray" name="head_hokuyo_sensor">
      <pose>0 0 0 0 0 0</pose>
      <visualize>true</visualize>
      <update_rate>40</update_rate>
      <ray>
        <scan>
          <horizontal>
            <samples>720</samples>
            <resolution>1</resolution>
            <min_angle>1.57</min_angle>
            <max_angle>-1.57</max_angle>
          </horizontal>
        </scan>
        <range>
          <min>0.1</min>
          <max>5.0</max>
          <resolution>0.1</resolution>
        </range>
        <noise>
          <type>gaussian</type>
          <!-- Noise parameters based on published spec for Hokuyo laser
               achieving "+-30mm" accuracy at range < 10m.  A mean of 0.0m and
               stddev of 0.01m will put 99.7% of samples within 0.03m of the true
               reading. -->
          <mean>0.0</mean>
          <stddev>0.01</stddev>
        </noise>
      </ray>
      <plugin name="gazebo_ros_head_hokuyo_controller" filename="libgazebo_ros_laser.so">
        <topicName>/mbot/laser/scan</topicName>
        <frameName>hokuyo_link</frameName>
      </plugin>
    </sensor>
  </gazebo>

  <!-- Camera -->
  <link name="camera_link">
    <collision>
      <origin xyz="0 0 0" rpy="0 0 0"/>
      <geometry>
    <box size="${camera_link} ${camera_link} ${camera_link}"/>
      </geometry>
    </collision>

    <visual>
      <origin xyz="0 0 0" rpy="0 0 0"/>
      <geometry>
    <box size="${camera_link} ${camera_link} ${camera_link}"/>
      </geometry>
      <material name="red"/>
    </visual>

    <inertial>
      <mass value="1e-5" />
      <origin xyz="0 0 0" rpy="0 0 0"/>
      <inertia ixx="1e-6" ixy="0" ixz="0" iyy="1e-6" iyz="0" izz="1e-6" />
    </inertial>
  </link>

  <joint name="camera_joint" type="fixed">
    <origin xyz="0 -0.14 0" rpy="0 0 -1.57"/>
    <parent link="head"/>
    <child link="camera_link"/>
  </joint>

  <!-- camera -->
  <gazebo reference="camera_link">
    <sensor type="camera" name="camera1">
      <update_rate>15.0</update_rate>
      <camera name="head">
        <horizontal_fov>1.3962634</horizontal_fov>
        <image>
          <width>640</width>
          <height>360</height>
          <format>R8G8B8</format>
        </image>
        <clip>
          <near>0.02</near>
          <far>300</far>
        </clip>
        <noise>
          <type>gaussian</type>
          <!-- Noise is sampled independently per pixel on each frame.
               That pixel's noise value is added to each of its color
               channels, which at that point lie in the range [0,1]. -->
          <mean>0.0</mean>
          <stddev>0.007</stddev>
        </noise>
      </camera>
      <plugin name="camera_controller" filename="libgazebo_ros_camera.so">
        <alwaysOn>true</alwaysOn>
        <updateRate>0.0</updateRate>
        <cameraName>mbot/camera1</cameraName>
        <imageTopicName>image_raw</imageTopicName>
        <cameraInfoTopicName>camera_info</cameraInfoTopicName>
        <frameName>camera_link</frameName>
        <hackBaseline>0.07</hackBaseline>
        <distortionK1>0.0</distortionK1>
        <distortionK2>0.0</distortionK2>
        <distortionK3>0.0</distortionK3>
        <distortionT1>0.0</distortionT1>
        <distortionT2>0.0</distortionT2>
      </plugin>
    </sensor>
  </gazebo>


  <!-- IMU -->
  <link name="imu_link">
    <collision>
      <origin xyz="0 0 0" rpy="0 0 0"/>
      <geometry>
    <box size="${imu_link} ${imu_link} ${imu_link}"/>
      </geometry>
    </collision>

    <visual>
      <origin xyz="0 0 0" rpy="0 0 0"/>
      <geometry>
    <box size="${imu_link} ${imu_link} ${imu_link}"/>
      </geometry>
    </visual>

    <inertial>
      <mass value="1e-5" />
      <origin xyz="0 0 0" rpy="0 0 0"/>
      <inertia ixx="1e-6" ixy="0" ixz="0" iyy="1e-6" iyz="0" izz="1e-6" />
    </inertial>
  </link>

  <joint name="imu_joint" type="fixed">
    <origin xyz="0 0 0"/>
    <parent link="base_link"/>
    <child link="imu_link"/>
  </joint>

  <gazebo>
    <plugin name="imu_controller" filename="libgazebo_ros_imu.so">
      <alwaysOn>true</alwaysOn>
      <updateRate>50.0</updateRate>
      <robotNamespace>mbot</robotNamespace> 
      <bodyName>imu_link</bodyName>
      <topicName>imu_data</topicName>
      <gaussianNoise>2.89e-08</gaussianNoise>
      <xyzOffsets>0 0 0</xyzOffsets>
      <rpyOffsets>0 0 0</rpyOffsets>
      <position name="imu_position"/>
    </plugin>
  </gazebo>

  <gazebo>
    <plugin name="skid_steer_drive_controller" filename="libgazebo_ros_skid_steer_drive.so">
      <updateRate>50.0</updateRate>
      <robotNamespace>/</robotNamespace>
      <leftFrontJoint>left_front_wheel_joint</leftFrontJoint>
      <rightFrontJoint>right_front_wheel_joint</rightFrontJoint>
      <leftRearJoint>left_back_wheel_joint</leftRearJoint>
      <rightRearJoint>right_back_wheel_joint</rightRearJoint>
      <wheelSeparation>0.2</wheelSeparation>
      <wheelDiameter>0.035</wheelDiameter>
      <robotBaseFrame>base_link</robotBaseFrame>
      <torque>5</torque>
      <topicName>/cmd_vel</topicName>
      <commandTopic>cmd_vel</commandTopic>
      <odometryTopic>/mbot/odom</odometryTopic>
      <odometryFrame>odom</odometryFrame>
      <childFrame>base_link</childFrame>
      <broadcastTF>true</broadcastTF>
    </plugin>
  </gazebo>  

  <gazebo reference="base_link">
    <material>Gazebo/Orange</material>
  </gazebo>

  <gazebo reference="head">
    <material>Gazebo/Blue</material>
  </gazebo>

  <gazebo reference="right_front_wheel">
    <material>Gazebo/Black</material>
  </gazebo>

  <gazebo reference="right_back_wheel">
    <material>Gazebo/Black</material>
  </gazebo>

  <gazebo reference="left_front_wheel">
    <material>Gazebo/Black</material>
  </gazebo>

  <gazebo reference="left_back_wheel">
    <material>Gazebo/Black</material>
  </gazebo>

  <gazebo reference="hand_right">
    <material>Gazebo/Yellow</material>
  </gazebo>

  <gazebo reference="hand_left">
    <material>Gazebo/Yellow</material>
  </gazebo>

  <gazebo>
    <plugin name="gazebo_ros_control" filename="libgazebo_ros_control.so">
      <robotNamespace>/mbot</robotNamespace>
    </plugin>
  </gazebo>

  <!-- <transmission name="right_hand_transmission">
    <type>transmission_interface/SimpleTransmission</type>
    <joint name="right_hand_base_joint">
      <hardwareInterface>EffortJointInterface</hardwareInterface>
    </joint>
    <actuator name="right_hand_joint_motor">
      <hardwareInterface>EffortJointInterface</hardwareInterface>
      <mechanicalReduction>1</mechanicalReduction>
    </actuator>
  </transmission>

  <transmission name="left_hand_transmission">
    <type>transmission_interface/SimpleTransmission</type>
    <joint name="left_hand_base_joint">
      <hardwareInterface>EffortJointInterface</hardwareInterface>
    </joint>
    <actuator name="left_hand_joint_motor">
      <hardwareInterface>EffortJointInterface</hardwareInterface>
      <mechanicalReduction>1</mechanicalReduction>
    </actuator>
  </transmission> -->


</robot>
